Workbook

Sheet original data
A1: Country_name | B1: Life Ladder | C1: Average Life Ladder | D1: Log GDP per capita | E1: Social_support | F1: Healthy life expectancy at birth | G1: Freedom_to_make_life_choices | H1: Generosity | I1: Perceptions_of_corruption | J1: Positive affect | K1: Negative affect | L1: Confidence in national government
A2: Austria | B2: 7.2134891 | C2: =AVERAGEIF(A:A, A2, B:B) -> 7.1628304 | D2: 10.85622 | E2: 0.92483121 | F2: 71.025002 | G2: 0.91190988 | H2: 0.008043503 | I2: 0.46383017 | J2: 0.71635228 | K2: 0.20649965 | L2: 0.62617785
A3: Austria | B3: 7.1953611 | C3: =AVERAGEIF(A:A, A3, B:B) -> 7.1628304 | D3: 10.93013 | E3: 0.9644888 | F3: 70.900002 | G3: 0.90342766 | H3: 0.05765314 | I3: 0.45708889 | J3: 0.72734111 | K3: 0.20516974 | L3: 0.51233828
A4: Austria | B4: 7.0796409 | C4: =AVERAGEIF(A:A, A4, B:B) -> 7.1628304 | D4: 10.892092 | E4: 0.86297596 | F4: 71.150002 | G4: 0.79484594 | H4: 0.16167346 | I4: 0.5008086 | J4: 0.72186524 | K4: 0.25908017 | L4: 0.61045897
A5: Belgium | B5: 6.8387609 | C5: =AVERAGEIF(A:A, A5, B:B) -> 6.8054495 | D5: 10.793847 | E5: 0.90355867 | F5: 70.75 | G5: 0.76691783 | H5: -0.16801377 | I5: 0.63362676 | J5: 0.61912548 | K5: 0.26018879 | L5: 0.2947996
A6: Belgium | B6: 6.7721381 | C6: =AVERAGEIF(A:A, A6, B:B) -> 6.8054495 | D6: 10.857924 | E6: 0.88423049 | F6: 70.599998 | G6: 0.77620363 | H6: -0.17447265 | I6: 0.67249751 | J6: 0.6990425 | K6: 0.24363084 | L6: 0.32790115
A7: Brazil | B7: 6.320673 | C7: =AVERAGEIF(A:A, A7, B:B) -> 6.5152433 | D7: 9.5152473 | E7: 0.88640243 | F7: 63.419998 | G7: 0.77664483 | H7: -0.017624738 | I7: 0.72803849 | J7: 0.77485615 | K7: 0.29922277 | L7: 0.3834596
A8: Brazil | B8: 6.6914248 | C8: =AVERAGEIF(A:A, A8, B:B) -> 6.5152433 | D8: 9.5549917 | E8: 0.87810755 | F8: 63.580002 | G8: 0.7819311 | H8: -0.079088137 | I8: 0.68827277 | J8: 0.71765608 | K8: 0.26548552 | L8: 0.51101005
A9: Brazil | B9: 6.0099535 | C9: =AVERAGEIF(A:A, A9, B:B) -> 6.5152433 | D9: 9.5931873 | E9: 0.81432867 | F9: 65.75 | G9: 0.79150772 | H9: 0.090771444 | I9: 0.7385714 | J9: 0.6615504 | K9: 0.40718296 | L9: 0.32709929
A10: Brazil | B10: 6.6367712 | C10: =AVERAGEIF(A:A, A10, B:B) -> 6.5152433 | D10: 9.4387455 | E10: 0.88292295 | F10: 63.099998 | G10: 0.88218611 | I10: 0.74499404 | J10: 0.76992124 | K10: 0.30177984 | L10: 0.34062475
A11: Brazil | B11: 6.1097178 | C11: =AVERAGEIF(A:A, A11, B:B) -> 6.5152433 | D11: 9.5513725 | E11: 0.83083212 | F11: 65.574997 | G11: 0.78623509 | H11: -0.056306385 | I11: 0.72877222 | J11: 0.65329963 | K11: 0.38913855 | L11: 0.36229241
A12: Brazil | B12: 7.0008316 | C12: =AVERAGEIF(A:A, A12, B:B) -> 6.5152433 | D12: 9.5441132 | E12: 0.91281807 | F12: 63.740002 | G12: 0.76671606 | H12: -0.056668513 | I12: 0.72251499 | J12: 0.74398255 | K12: 0.27410316 | L12: 0.42717853
A13: Brazil | B13: 6.8373313 | C13: =AVERAGEIF(A:A, A13, B:B) -> 6.5152433 | D13: 9.607317 | E13: 0.90552813 | F13: 63.900002 | G13: 0.80594927 | H13: -0.055444442 | I13: 0.65603608 | J13: 0.72593129 | K13: 0.24988122 | L13: 0.51126665
A14: Belize | B14: 6.4506445 | C14: =AVERAGEIF(A:A, A14, B:B) -> 6.2031455 | D14: 8.9042778 | E14: 0.87226665 | F14: 64.300003 | G14: 0.70530593 | H14: 0.031119337 | I14: 0.76898444 | J14: 0.73154014 | K14: 0.25059572 | L14: 0.25546312
A15: Belize | B15: 5.9556465 | C15: =AVERAGEIF(A:A, A15, B:B) -> 6.2031455 | D15: 8.8987589 | E15: 0.7569325 | F15: 65 | G15: 0.87356907 | H15: 0.02009221 | I15: 0.78210539 | J15: 0.73502713 | K15: 0.28160441 | L15: 0.38426718
A16: Argentina | B16: 6.0731583 | C16: =AVERAGEIF(A:A, A16, B:B) -> 6.0311928 | D16: 10.017892 | E16: 0.86220557 | F16: 65.940002 | G16: 0.65283263 | H16: -0.1426135 | I16: 0.88105774 | J16: 0.74982589 | K16: 0.27900797 | L16: 0.40582374
A17: Argentina | B17: 5.9005671 | C17: =AVERAGEIF(A:A, A17, B:B) -> 6.0311928 | D17: 9.8878994 | E17: 0.89710385 | F17: 67.150002 | G17: 0.82339162 | H17: -0.12674294 | I17: 0.81578046 | J17: 0.67931676 | K17: 0.34249693 | L17: 0.43075809
A18: Argentina | B18: 6.3129253 | C18: =AVERAGEIF(A:A, A18, B:B) -> 6.0311928 | D18: 9.9416332 | E18: 0.93846279 | F18: 65.82 | G18: 0.73300368 | H18: -0.15844044 | I18: 0.85179949 | J18: 0.74828309 | K18: 0.32823002 | L18: 0.5175041
A19: Argentina | B19: 5.9082789 | C19: =AVERAGEIF(A:A, A19, B:B) -> 6.0311928 | D19: 9.9554214 | E19: 0.88230455 | F19: 67.199997 | G19: 0.81947935 | H19: -0.008816142 | I19: 0.8162567 | J19: 0.68486005 | K19: 0.34513158 | L19: 0.32657412
A20: Argentina | B20: 5.9610343 | C20: =AVERAGEIF(A:A, A20, B:B) -> 6.0311928 | D20: 10.047737 | E20: 0.89219451 | F20: 66.059998 | G20: 0.67822218 | H20: -0.13339715 | I20: 0.86499625 | J20: 0.71999699 | K20: 0.31822228 | L20: 0.28637058
A21: Bahrain | B21: 4.823976 | C21: =AVERAGEIF(A:A, A21, B:B) -> 5.6356533 | D21: 10.695518 | E21: 0.90786773 | F21: 65.239998 | G21: 0.86987037 | H21: -0.053820446 | I21: 0.58252245 | J21: 0.50599247 | K21: 0.5137192
A22: Bahrain | B22: 5.7005234 | C22: =AVERAGEIF(A:A, A22, B:B) -> 5.6356533 | D22: 10.709057 | E22: 0.90414345 | F22: 64.760002 | G22: 0.89593142 | H22: 0.03495907 | I22: 0.50610393 | J22: 0.70742238 | K22: 0.42188948
A23: Bahrain | B23: 5.0271869 | C23: =AVERAGEIF(A:A, A23, B:B) -> 5.6356533 | D23: 10.715217 | E23: 0.9113496 | F23: 65.480003 | G23: 0.6818229 | I23: 0.43791527 | J23: 0.55941576 | K23: 0.38081476
A24: Bahrain | B24: 5.9368691 | C24: =AVERAGEIF(A:A, A24, B:B) -> 5.6356533 | D24: 10.705484 | E24: 0.87711507 | F24: 65 | G24: 0.86200291 | H24: -0.003043235 | I24: 0.71462017 | J24: 0.64103901 | K24: 0.42267072
A25: Bahrain | B25: 6.6897111 | C25: =AVERAGEIF(A:A, A25, B:B) -> 5.6356533 | D25: 10.75643 | E25: 0.88378054 | F25: 65.720001 | G25: 0.80920595 | I25: 0.52470326 | J25: 0.71110761 | K25: 0.30620941
A26: Bolivia | B26: 5.3739862 | C26: =AVERAGEIF(A:A, A26, B:B) -> 5.5964644 | D26: 8.6862116 | E26: 0.83427995 | F26: 60.900002 | G26: 0.77013475 | H26: -0.044768732 | I26: 0.7944842 | J26: 0.708094 | K26: 0.43194497 | L26: 0.53630942
A27: Bolivia | B27: 5.2978725 | C27: =AVERAGEIF(A:A, A27, B:B) -> 5.5964644 | D27: 8.756403 | E27: 0.78526235 | F27: 61.299999 | G27: 0.72561973 | H27: -0.092359528 | I27: 0.80142039 | J27: 0.72347772 | K27: 0.39207962 | L27: 0.4418211
A28: Bolivia | B28: 5.6284194 | C28: =AVERAGEIF(A:A, A28, B:B) -> 5.5964644 | D28: 8.7136459 | E28: 0.7961365 | F28: 61.099998 | G28: 0.77993524 | H28: 6.16e-05 | I28: 0.81699395 | J28: 0.74573493 | K28: 0.38778624 | L28: 0.50628591
A29: Bolivia | B29: 6.0855794 | C29: =AVERAGEIF(A:A, A29, B:B) -> 5.5964644 | D29: 8.7727604 | E29: 0.83131993 | F29: 61.5 | G29: 0.77893859 | H29: -0.036766574 | I29: 0.76260454 | J29: 0.74209881 | K29: 0.37236929 | L29: 0.4681505
A30: Belarus | B30: 5.5529151 | C30: =AVERAGEIF(A:A, A30, B:B) -> 5.5765529 | D30: 9.8177176 | E30: 0.9002558 | F30: 65.550003 | G30: 0.62097925 | H30: -0.12349504 | I30: 0.65411341 | J30: 0.50173569 | K30: 0.23276807 | L30: 0.4479163
A31: Belarus | B31: 5.2337699 | C31: =AVERAGEIF(A:A, A31, B:B) -> 5.5765529 | D31: 9.8508615 | E31: 0.90456927 | F31: 65.775002 | G31: 0.64360237 | H31: -0.17650361 | I31: 0.71845549 | J31: 0.40888357 | K31: 0.23572862 | L31: 0.42127868
A32: Belarus | B32: 5.65765 | C32: =AVERAGEIF(A:A, A32, B:B) -> 5.5765529 | D32: 9.4890985 | E32: 0.91789866 | F32: 60.060001 | G32: 0.70708048 | H32: -0.24734436 | I32: 0.70827472 | J32: 0.53511918 | K32: 0.26940036 | L32: 0.59328771
A33: Belarus | B33: 5.8214531 | C33: =AVERAGEIF(A:A, A33, B:B) -> 5.5765529 | D33: 9.8667822 | E33: 0.91674048 | F33: 66 | G33: 0.65693361 | H33: -0.18811047 | I33: 0.54590476 | J33: 0.55898947 | K33: 0.18982141 | L33: 0.4608126
A34: Belarus | B34: 5.6169763 | C34: =AVERAGEIF(A:A, A34, B:B) -> 5.5765529 | D34: 9.5761881 | E34: 0.85752767 | F34: 60.619999 | G34: 0.66729951 | H34: -0.22623062 | I34: 0.69484943 | J34: 0.50245601 | K34: 0.2349814 | L34: 0.54361439
A35: Algeria | B35: 4.7446275 | C35: =AVERAGEIF(A:A, A35, B:B) -> 5.2360323 | D35: 9.3520126 | E35: 0.80325866 | F35: 66.400002 | G35: 0.38508344 | H35: 0.002798254 | I35: 0.74060935 | J35: 0.54442781 | K35: 0.21519776
A36: Algeria | B36: 5.3171945 | C36: =AVERAGEIF(A:A, A36, B:B) -> 5.2360323 | D36: 9.3127375 | E36: 0.81023449 | F36: 65.599998 | G36: 0.52956128 | H36: -0.18297538 | I36: 0.63798165 | J36: 0.50273627 | K36: 0.25489664
A37: Algeria | B37: 5.4635668 | C37: =AVERAGEIF(A:A, A37, B:B) -> 5.2360323 | D37: 9.3029823 | F37: 65.5 | G37: 0.59269583 | H37: -0.20763209 | I37: 0.61803788
A38: Algeria | B38: 5.4377551 | C38: =AVERAGEIF(A:A, A38, B:B) -> 5.2360323 | D38: 9.2813005 | E38: 0.8676489 | F38: 66.5 | G38: 0.57389069 | H38: -0.11853615 | I38: 0.72426367 | J38: 0.52416921 | K38: 0.31062976
A39: Algeria | B39: 5.2170177 | C39: =AVERAGEIF(A:A, A39, B:B) -> 5.2360323 | D39: 9.3035164 | E39: 0.84071028 | F39: 66.599998 | G39: 0.55848694 | H39: -0.11119115 | I39: 0.71190005 | J39: 0.49802229 | K39: 0.25777915
A40: Bhutan | B40: 5.5690918 | C40: =AVERAGEIF(A:A, A40, B:B) -> 5.1965995 | D40: 9.1229906 | E40: 0.81894898 | F40: 62.240002 | G40: 0.81020147 | H40: 0.35163271 | I40: 0.80242813 | J40: 0.66367561 | K40: 0.2173499 | L40: 0.97950077
...

Sheet Country Averages
A1: Country_name | B1: Average Life Ladder
A2: Austria | B2: =AVERAGEIF('original data'!A:A, A2, 'original data'!B:B) -> 7.1628304
A3: Belgium | B3: =AVERAGEIF('original data'!A:A, A3, 'original data'!B:B) -> 6.8054495
A4: Brazil | B4: =AVERAGEIF('original data'!A:A, A4, 'original data'!B:B) -> 6.5152433
A5: Belize | B5: =AVERAGEIF('original data'!A:A, A5, 'original data'!B:B) -> 6.2031455
A6: Argentina | B6: =AVERAGEIF('original data'!A:A, A6, 'original data'!B:B) -> 6.0311928
A7: Bahrain | B7: =AVERAGEIF('original data'!A:A, A7, 'original data'!B:B) -> 5.6356533
A8: Bolivia | B8: =AVERAGEIF('original data'!A:A, A8, 'original data'!B:B) -> 5.5964644
A9: Belarus | B9: =AVERAGEIF('original data'!A:A, A9, 'original data'!B:B) -> 5.5765529
A10: Algeria | B10: =AVERAGEIF('original data'!A:A, A10, 'original data'!B:B) -> 5.2360323
A11: Bhutan | B11: =AVERAGEIF('original data'!A:A, A11, 'original data'!B:B) -> 5.1965995
A12: Albania | B12: =AVERAGEIF('original data'!A:A, A12, 'original data'!B:B) -> 5.051932
A13: Azerbaijan | B13: =AVERAGEIF('original data'!A:A, A13, 'original data'!B:B) -> 4.9344807
... A22: Benin | B22: =AVERAGEIF('original data'!A:A, A22, 'original data'!B:B) -> 3.6224069
